Workbook

Sheet Parameters
A1: Parameter | B1: Value
A2: Probability | B2: 0.95
A3: Mean (age) | B3: 40
A4: StdDev (age) | B4: 12

Sheet Data
A1: Age | B1: Group
A2: 30.667002 | B2: 3
A3: 36.335168 | B3: 3
A4: 33.424059 | B4: 4
A5: 52.576528 | B5: 4
A6: 48.466306 | B6: 3
A7: 36.752011 | B7: 4
A8: 22.097907 | B8: 1
A9: 61.275854 | B9: 3
A10: 50.570993 | B10: 3
A11: 35.273007 | B11: 3
A12: 46.206612 | B12: 3
A13: 33.598833 | B13: 2
... A251: 32.538608 | B251: 3

Sheet Sample
A1: Age | B1: Group | C1: Sample (by group) | E1: Chosen group
A2: =Data!A2 -> 30.667002 | B2: =Data!B2 -> 3 | C2: =IF(B2=$E$2,A2,"") | E2: 1
A3: =Data!A3 -> 36.335168 | B3: =Data!B3 -> 3 | C3: =IF(B3=$E$2,A3,"")
A4: =Data!A4 -> 33.424059 | B4: =Data!B4 -> 4 | C4: =IF(B4=$E$2,A4,"")
A5: =Data!A5 -> 52.576528 | B5: =Data!B5 -> 4 | C5: =IF(B5=$E$2,A5,"")
A6: =Data!A6 -> 48.466306 | B6: =Data!B6 -> 3 | C6: =IF(B6=$E$2,A6,"")
A7: =Data!A7 -> 36.752011 | B7: =Data!B7 -> 4 | C7: =IF(B7=$E$2,A7,"")
A8: =Data!A8 -> 22.097907 | B8: =Data!B8 -> 1 | C8: =IF(B8=$E$2,A8,"") -> 22.097907
A9: =Data!A9 -> 61.275854 | B9: =Data!B9 -> 3 | C9: =IF(B9=$E$2,A9,"")
A10: =Data!A10 -> 50.570993 | B10: =Data!B10 -> 3 | C10: =IF(B10=$E$2,A10,"")
A11: =Data!A11 -> 35.273007 | B11: =Data!B11 -> 3 | C11: =IF(B11=$E$2,A11,"")
A12: =Data!A12 -> 46.206612 | B12: =Data!B12 -> 3 | C12: =IF(B12=$E$2,A12,"")
A13: =Data!A13 -> 33.598833 | B13: =Data!B13 -> 2 | C13: =IF(B13=$E$2,A13,"")
A14: =Data!A14 -> 45.913557 | B14: =Data!B14 -> 1 | C14: =IF(B14=$E$2,A14,"") -> 45.913557
... A251: =Data!A251 -> 32.538608 | B251: =Data!B251 -> 3 | C251: =IF(B251=$E$2,A251,"")

Sheet Statistical Insight
A1: Measure | B1: Value
A2: STDDEV | B2: =STDEV(Sample!C2:C251) -> 11.178629
A3: EXPECTED VALUE | B3: =AVERAGE(Sample!C2:C251) -> 42.240025
A4: COUNT | B4: =COUNT(Sample!C2:C251) -> 53
A5: CONFIDENCE RATE | B5: =Parameters!B2 -> 0.95
A6: ESTIMATION OF P PARAMETER | B6: =2*MIN(ZTEST(Sample!C2:C251,Parameters!B3,Parameters!B4),1-ZTEST(Sample!C2:C251,Parameters!B3,Parameters!B4)) -> 0.17415648
A7: CONFIDENCE INTERVAL | B7: ="[" & TEXT(B8,"0,00") & " ; " & TEXT(B9,"0,00") & "]" -> [39,23 ; 45,25]
A8: LOWER BOUND CI | B8: =B3-_xlfn.NORM.S.INV(0.975)*B2/SQRT(B4) -> 39.230494
A9: UPPER BOUND CI | B9: =B3+_xlfn.NORM.S.INV(0.975)*B2/SQRT(B4) -> 45.249555

Sheet (Un)correlated Variables
A1: Sample data | B1: Number of cats | C1: Age of partner | E1: Corr(Age, Number of cats) | F1: Corr(Age, Age of partner)
A2: =Sample!C8 -> 22.097907 | B2: 2 | C2: 17.097907 | E2: =CORREL(A2:A54,B2:B54) -> 0.15989685 | F2: =CORREL(A2:A54,C2:C54) -> 0.96062255
A3: =Sample!C14 -> 45.913557 | B3: 2 | C3: 41.913557
A4: =Sample!C15 -> 39.776335 | B4: 4 | C4: 39.776335
A5: =Sample!C26 -> 53.437461 | B5: 2 | C5: 49.437461
A6: =Sample!C32 -> 59.200101 | B6: 1 | C6: 63.200101
A7: =Sample!C44 -> 31.091472 | B7: 4 | C7: 36.091472
A8: =Sample!C55 -> 53.437103 | B8: 2 | C8: 58.437103
A9: =Sample!C56 -> 39.345025 | B9: 4 | C9: 41.345025
A10: =Sample!C59 -> 33.713158 | B10: 2 | C10: 38.713158
A11: =Sample!C66 -> 29.475622 | B11: 0 | C11: 31.475622
A12: =Sample!C73 -> 41.914769 | B12: 5 | C12: 42.914769
A13: =Sample!C81 -> 42.117101 | B13: 4 | C13: 47.117101
A14: =Sample!C82 -> 38.26586 | B14: 4 | C14: 42.26586
A15: =Sample!C99 -> 65.066475 | B15: 2 | C15: 62.066475
A16: =Sample!C103 -> 55.402626 | B16: 4 | C16: 59.402626
A17: =Sample!C104 -> 38.317191 | B17: 2 | C17: 36.317191
A18: =Sample!C105 -> 50.369456 | B18: 2 | C18: 45.369456
A19: =Sample!C109 -> 42.272426 | B19: 4 | C19: 42.272426
A20: =Sample!C110 -> 28.638854 | B20: 1 | C20: 33.638854
A21: =Sample!C116 -> 41.238364 | B21: 2 | C21: 44.238364
A22: =Sample!C121 -> 49.224365 | B22: 5 | C22: 45.224365
A23: =Sample!C123 -> 48.665996 | B23: 4 | C23: 44.665996
A24: =Sample!C126 -> 38.551778 | B24: 5 | C24: 35.551778
A25: =Sample!C127 -> 57.69648 | B25: 0 | C25: 62.69648
A26: =Sample!C128 -> 50.65251 | B26: 0 | C26: 53.65251
A27: =Sample!C133 -> 17.516341 | B27: 1 | C27: 13.516341
A28: =Sample!C138 -> 34.549767 | B28: 3 | C28: 32.549767
A29: =Sample!C139 -> 45.701794 | B29: 5 | C29: 45.701794
A30: =Sample!C145 -> 48.646369 | B30: 2 | C30: 51.646369
A31: =Sample!C148 -> 53.561895 | B31: 4 | C31: 56.561895
A32: =Sample!C152 -> 43.222204 | B32: 5 | C32: 40.222204
A33: =Sample!C153 -> 16.692395 | B33: 1 | C33: 12.692395
A34: =Sample!C160 -> 44.955162 | B34: 2 | C34: 49.955162
A35: =Sample!C164 -> 58.94843 | B35: 5 | C35: 55.94843
A36: =Sample!C165 -> 51.655531 | B36: 1 | C36: 52.655531
A37: =Sample!C169 -> 59.192763 | B37: 5 | C37: 61.192763
A38: =Sample!C172 -> 37.164786 | B38: 1 | C38: 34.164786
A39: =Sample!C175 -> 33.782286 | B39: 4 | C39: 29.782286
A40: =Sample!C187 -> 48.964054 | B40: 3 | C40: 51.964054
...

Sheet Linear Regression
A1: Y (age) | B1: X (rank) | C1: Slope | D1: Intercept | E1: Regression line | F1: Predicted age (X=160) | G1: Fitted age | I1: R-squared | J1: ="Linear Regression (R² ≈ " & TEXT(I2,"0,000000") & ")" -> Linear Regression (R² ≈ 0,000007)
A2: =Data!A2 -> 30.667002 | B2: 1 | C2: =SLOPE(A2:A251,B2:B251) -> -0.00038943849 | D2: =INTERCEPT(A2:A251,B2:B251) -> 39.3127 | E2: ="Y = " & TEXT($C$2,"0,000") & " * X + " & TEXT($D$2,"0,000") -> Y = 0,000 * X + 39,313 | F2: =$C$2*160 + $D$2 -> 39.25039 | G2: =$C$2*B2 + $D$2 -> 39.312311 | I2: =CORREL(A2:A251,B2:B251)^2 -> 7.2879416e-06
A3: =Data!A3 -> 36.335168 | B3: 2 | C3: =SLOPE(A3:A252,B3:B252) -> -0.0012294413 | D3: =INTERCEPT(A3:A252,B3:B252) -> 39.453261 | E3: ="Y = " & TEXT($C$2,"0,000") & " * X + " & TEXT($D$2,"0,000") -> Y = 0,000 * X + 39,313 | F3: =$C$2*160 + $D$2 -> 39.25039 | G3: =$C$2*B3 + $D$2 -> 39.311921
A4: =Data!A4 -> 33.424059 | B4: 3 | C4: =SLOPE(A4:A253,B4:B253) -> -0.0015346164 | D4: =INTERCEPT(A4:A253,B4:B253) -> 39.504429 | E4: ="Y = " & TEXT($C$2,"0,000") & " * X + " & TEXT($D$2,"0,000") -> Y = 0,000 * X + 39,313 | F4: =$C$2*160 + $D$2 -> 39.25039 | G4: =$C$2*B4 + $D$2 -> 39.311532
A5: =Data!A5 -> 52.576528 | B5: 4 | C5: =SLOPE(A5:A254,B5:B254) -> -0.0021345735 | D5: =INTERCEPT(A5:A254,B5:B254) -> 39.605221 | E5: ="Y = " & TEXT($C$2,"0,000") & " * X + " & TEXT($D$2,"0,000") -> Y = 0,000 * X + 39,313 | F5: =$C$2*160 + $D$2 -> 39.25039 | G5: =$C$2*B5 + $D$2 -> 39.311143
A6: =Data!A6 -> 48.466306 | B6: 5 | C6: =SLOPE(A6:A255,B6:B255) -> -0.0008424038 | D6: =INTERCEPT(A6:A255,B6:B255) -> 39.387706 | E6: ="Y = " & TEXT($C$2,"0,000") & " * X + " & TEXT($D$2,"0,000") -> Y = 0,000 * X + 39,313 | F6: =$C$2*160 + $D$2 -> 39.25039 | G6: =$C$2*B6 + $D$2 -> 39.310753
A7: =Data!A7 -> 36.752011 | B7: 6 | C7: =SLOPE(A7:A256,B7:B256) -> 6.9219976e-05 | D7: =INTERCEPT(A7:A256,B7:B256) -> 39.233946 | E7: ="Y = " & TEXT($C$2,"0,000") & " * X + " & TEXT($D$2,"0,000") -> Y = 0,000 * X + 39,313 | F7: =$C$2*160 + $D$2 -> 39.25039 | G7: =$C$2*B7 + $D$2 -> 39.310364
A8: =Data!A8 -> 22.097907 | B8: 7 | C8: =SLOPE(A8:A257,B8:B257) -> -0.0001819792 | D8: =INTERCEPT(A8:A257,B8:B257) -> 39.276398 | E8: ="Y = " & TEXT($C$2,"0,000") & " * X + " & TEXT($D$2,"0,000") -> Y = 0,000 * X + 39,313 | F8: =$C$2*160 + $D$2 -> 39.25039 | G8: =$C$2*B8 + $D$2 -> 39.309974
A9: =Data!A9 -> 61.275854 | B9: 8 | C9: =SLOPE(A9:A258,B9:B258) -> -0.0019345776 | D9: =INTERCEPT(A9:A258,B9:B258) -> 39.573172 | E9: ="Y = " & TEXT($C$2,"0,000") & " * X + " & TEXT($D$2,"0,000") -> Y = 0,000 * X + 39,313 | F9: =$C$2*160 + $D$2 -> 39.25039 | G9: =$C$2*B9 + $D$2 -> 39.309585
A10: =Data!A10 -> 50.570993 | B10: 9 | C10: =SLOPE(A10:A259,B10:B259) -> 0.00029972426 | D10: =INTERCEPT(A10:A259,B10:B259) -> 39.194085 | E10: ="Y = " & TEXT($C$2,"0,000") & " * X + " & TEXT($D$2,"0,000") -> Y = 0,000 * X + 39,313 | F10: =$C$2*160 + $D$2 -> 39.25039 | G10: =$C$2*B10 + $D$2 -> 39.309195
A11: =Data!A11 -> 35.273007 | B11: 10 | C11: =SLOPE(A11:A260,B11:B260) -> 0.0014796217 | D11: =INTERCEPT(A11:A260,B11:B260) -> 38.993502 | E11: ="Y = " & TEXT($C$2,"0,000") & " * X + " & TEXT($D$2,"0,000") -> Y = 0,000 * X + 39,313 | F11: =$C$2*160 + $D$2 -> 39.25039 | G11: =$C$2*B11 + $D$2 -> 39.308806
A12: =Data!A12 -> 46.206612 | B12: 11 | C12: =SLOPE(A12:A261,B12:B261) -> 0.0010889008 | D12: =INTERCEPT(A12:A261,B12:B261) -> 39.060055 | E12: ="Y = " & TEXT($C$2,"0,000") & " * X + " & TEXT($D$2,"0,000") -> Y = 0,000 * X + 39,313 | F12: =$C$2*160 + $D$2 -> 39.25039 | G12: =$C$2*B12 + $D$2 -> 39.308417
A13: =Data!A13 -> 33.598833 | B13: 12 | C13: =SLOPE(A13:A262,B13:B262) -> 0.001841467 | D13: =INTERCEPT(A13:A262,B13:B262) -> 38.931617 | E13: ="Y = " & TEXT($C$2,"0,000") & " * X + " & TEXT($D$2,"0,000") -> Y = 0,000 * X + 39,313 | F13: =$C$2*160 + $D$2 -> 39.25039 | G13: =$C$2*B13 + $D$2 -> 39.308027
A14: =Data!A14 -> 45.913557 | B14: 13 | C14: =SLOPE(A14:A263,B14:B263) -> 0.0012718593 | D14: =INTERCEPT(A14:A263,B14:B263) -> 39.02902 | E14: ="Y = " & TEXT($C$2,"0,000") & " * X + " & TEXT($D$2,"0,000") -> Y = 0,000 * X + 39,313 | F14: =$C$2*160 + $D$2 -> 39.25039 | G14: =$C$2*B14 + $D$2 -> 39.307638
... A251: =Data!A251 -> 32.538608 | B251: 250 | C251: =SLOPE(A251:A500,B251:B500) -> #DIV/0! | D251: =INTERCEPT(A251:A500,B251:B500) -> #DIV/0! | E251: ="Y = " & TEXT($C$2,"0,000") & " * X + " & TEXT($D$2,"0,000") -> Y = 0,000 * X + 39,313 | F251: =$C$2*160 + $D$2 -> 39.25039 | G251: =$C$2*B251 + $D$2 -> 39.215341
